Traceback (most recent call last):
  File "/home/cplan/.local/lib/python3.10/site-packages/redis/connection.py", line 276, in connect
    sock = self.retry.call_with_retry(
  File "/home/cplan/.local/lib/python3.10/site-packages/redis/retry.py", line 46, in call_with_retry
    return do()
  File "/home/cplan/.local/lib/python3.10/site-packages/redis/connection.py", line 277, in <lambda>
    lambda: self._connect(), lambda error: self.disconnect(error)
  File "/home/cplan/.local/lib/python3.10/site-packages/redis/connection.py", line 639, in _connect
    raise err
  File "/home/cplan/.local/lib/python3.10/site-packages/redis/connection.py", line 627, in _connect
    sock.connect(socket_address)
ConnectionRefusedError: [Errno 111] Connection refused

During handling of the above exception, another exception occurred:

Traceback (most recent call last):
  File "/home/cplan/Data_Science/crawl.py", line 105, in <module>
    r.flushall()
  File "/home/cplan/.local/lib/python3.10/site-packages/redis/commands/core.py", line 932, in flushall
    return self.execute_command("FLUSHALL", *args, **kwargs)
  File "/home/cplan/.local/lib/python3.10/site-packages/redis/client.py", line 542, in execute_command
    conn = self.connection or pool.get_connection(command_name, **options)
  File "/home/cplan/.local/lib/python3.10/site-packages/redis/connection.py", line 1109, in get_connection
    connection.connect()
  File "/home/cplan/.local/lib/python3.10/site-packages/redis/connection.py", line 282, in connect
    raise ConnectionError(self._error_message(e))
redis.exceptions.ConnectionError: Error 111 connecting to localhost:6379. Connection refused.
